Workbook
Name PCEntradasN1_Nível_1: TbPCEntradasN1[[Nível 1 ]]
Name PCEntradasN2_Nível_1: TbPCEntradasN2[Nível 1]
Name PCEntradasN2_Nível_2: TbPCEntradasN2[Nível 2]
Name PCSaídasN1_Nível_1: TbPCSaídasN1[Nível 1]
Name PCSaídasN2_Nível_1: TbPCSaídasN2[Nível 1]
Name PCSaídasN2_Nível_2: TbPCSaídasN2[Nível 2]
Name SegmentaçãodeDados_Ano_Competência: #N/A
Name SegmentaçãodeDados_Ano_Competência1: #N/A
Name SegmentaçãodeDados_Ano_Competência2: #N/A
Name SegmentaçãodeDados_Ano_Previsto: #N/A
Name SegmentaçãodeDados_Ano_Previsto1: #N/A
Name SegmentaçãodeDados_Mês_Competência: #N/A
Name SegmentaçãodeDados_Mês_Competência1: #N/A
Name SegmentaçãodeDados_Mês_Previsto: #N/A
Name SegmentaçãodeDados_Mês_Previsto1: #N/A

Sheet Início
B1: (NOME DA EMPRESA) | N1: FLUXO DE CAIXA EMPRESARIAL
B3: Empresa
B4: (NOME DA EMPRESA)
B7: Responsável
B16: Desenvolvido por Vinícius Assumpção

Sheet Matriz
B1: (NOME DA EMPRESA) | N1: TÍTULO

Sheet PCEntradasN1
B1: (NOME DA EMPRESA) | N1: Plano de Contas de Entradas - Nível 1
B3: PLANO DE CONTAS DE ENTRADAS NÍVEL 1
B4: Nível 1
B5: Empréstimos de curto prazo
B6: Financiamentos de longo prazo
B7: Receitas Financeiras
B8: Venda de ativos
B9: Vendas de mercadorias

Sheet PCEntradasN2
B1: (NOME DA EMPRESA) | N1: Plano de Contas de Entradas - Nível 2
B3: PLANO DE CONTAS DE ENTRADAS NÍVEL 2
B4: Nível 1 | C4: Nível 2
B5: Empréstimos de curto prazo | C5: Empréstimos capital de giro
B6: Receitas Financeiras | C6: Juros sobre aplicações
B7: Venda de ativos | C7: Mobiliário próprio
B8: Vendas de mercadorias | C8: Eletrodomésticos
B9: Vendas de mercadorias | C9: Informática
B10: Vendas de mercadorias | C10: Livros
B11: Vendas de mercadorias | C11: Móveis
B12: Vendas de mercadorias | C12: Som e imagem
B13: Financiamentos de longo prazo | C13: Geral

Sheet PCSaídasN1
B1: (NOME DA EMPRESA) | N1: Plano de Contas de Saídas - Nível 1
B3: PLANO DE CONTAS DE SAÍDA NÍVEL 1
B4: Nível 1
B5: Compra de mercadorias
B6: Despesas administrativas
B7: Despesas comerciais
B8: Despesas financeiras
B9: Imposto de renda
B10: Impostos sobre as vendas

Sheet PCSaídasN2
B1: (NOME DA EMPRESA) | N1: Plano de Contas de Saídas - Nível 2
B3: PLANO DE CONTAS DE SAÍDAS NÍVEL 2
B4: Nível 1 | C4: Nível 2
B5: Compra de mercadorias | C5: Eletrodomésticos
B6: Compra de mercadorias | C6: Informática
B7: Compra de mercadorias | C7: Livros
B8: Compra de mercadorias | C8: Som e imagem
B9: Compra de mercadorias | C9: Vestuário
B10: Despesas administrativas | C10: Comunicação - internet e telefonia
B11: Despesas administrativas | C11: Energia elétrica
B12: Despesas comerciais | C12: Encargos sobre os salários dos vendedores
B13: Despesas comerciais | C13: Salários dos vendedores
B14: Despesas financeiras | C14: Juros sobre empréstimos
B15: Imposto de renda | C15: IR sobre o lucro presumido
B16: Impostos sobre as vendas | C16: Geral

Sheet RegistroEntradas
B1: (NOME DA EMPRESA) | H1: Registro das Entradas de Caixa
B3: Data do Caixa Realizado | C3: Data da Competência | D3: Data do Caixa Previsto | E3: Conta Nível 1 | F3: Conta Nível 2 | G3: Histórico | H3: Valor | I3: Mês Caixa | J3: Ano Caixa | K3: Mês Competência | L3: Ano Competência | M3: Mês Previsto | N3: Ano Previsto | O3: Conta Vencida | P3: Venda à Vista | Q3: Dias de Atraso
B4: 45551 | C4: 45514 | D4: 45529 | E4: Vendas de mercadorias | F4: Informática | G4: NF7238 | H4: 1133 | I4: =IF(TbRegistroEntradas[[#This Row],[Data do Caixa Realizado]]="",0,MONTH(TbRegistroEntradas[[#This Row],[Data do Caixa Previsto]])) -> 8 | J4: =IF(TbRegistroEntradas[[#This Row],[Data do Caixa Realizado]]="",0,YEAR(TbRegistroEntradas[[#This Row],[Data do Caixa Realizado]])) -> 2024 | K4: =IF(TbRegistroEntradas[[#This Row],[Data da Competência]]="",0,MONTH(TbRegistroEntradas[[#This Row],[Data da Competência]])) -> 8 | L4: =IF(TbRegistroEntradas[[#This Row],[Data da Competência]]="",0,YEAR(TbRegistroEntradas[[#This Row],[Data da Competência]])) -> 2024 | M4: =IF(TbRegistroEntradas[[#This Row],[Data do Caixa Previsto]]="",0,MONTH(TbRegistroEntradas[[#This Row],[Data do Caixa Previsto]])) -> 8 | N4: =IF(TbRegistroEntradas[[#This Row],[Data do Caixa Previsto]]="",0,YEAR(TbRegistroEntradas[[#This Row],[Data do Caixa Previsto]])) -> 2024 | O4: =IF(AND(TbRegistroEntradas[[#This Row],[Data do Caixa Previsto]]<TODAY(),TbRegistroEntradas[[#This Row],[Data do Caixa Realizado]]=""),"Vencida","Não Vencida") -> Não Vencida | P4: =IF(TbRegistroEntradas[[#This Row],[Data da Competência]]=TbRegistroEntradas[[#This Row],[Data do Caixa Previsto]],"Vista","Prazo") -> Prazo | Q4: =IF(TbRegistroEntradas[[#This Row],[Data do Caixa Realizado]]<>"", IF(TbRegistroEntradas[[#This Row],[Data do Caixa Realizado]]>TbRegistroEntradas[[#This Row],[Data do Caixa Previsto]], TbRegistroEntradas[[#This Row],[Data do Caixa Realizado]]-TbRegistroEntradas[[#This Row],[Data do Caixa Previsto]], 0 ), IF(TODAY()>TbRegistroEntradas[[#This Row],[Data do Caixa Previsto]], TODAY()-TbRegistroEntradas[[#This Row],[Data do Caixa Previsto]], 0 ) ) -> 22
B5: 45542 | C5: 45517 | D5: 45542 | E5: Vendas de mercadorias | F5: Móveis | G5: NF9147 | H5: 164 | I5: =IF(TbRegistroEntradas[[#This Row],[Data do Caixa Realizado]]="",0,MONTH(TbRegistroEntradas[[#This Row],[Data do Caixa Previsto]])) -> 9 | J5: =IF(TbRegistroEntradas[[#This Row],[Data do Caixa Realizado]]="",0,YEAR(TbRegistroEntradas[[#This Row],[Data do Caixa Realizado]])) -> 2024 | K5: =IF(TbRegistroEntradas[[#This Row],[Data da Competência]]="",0,MONTH(TbRegistroEntradas[[#This Row],[Data da Competência]])) -> 8 | L5: =IF(TbRegistroEntradas[[#This Row],[Data da Competência]]="",0,YEAR(TbRegistroEntradas[[#This Row],[Data da Competência]])) -> 2024 | M5: =IF(TbRegistroEntradas[[#This Row],[Data do Caixa Previsto]]="",0,MONTH(TbRegistroEntradas[[#This Row],[Data do Caixa Previsto]])) -> 9 | N5: =IF(TbRegistroEntradas[[#This Row],[Data do Caixa Previsto]]="",0,YEAR(TbRegistroEntradas[[#This Row],[Data do Caixa Previsto]])) -> 2024 | O5: =IF(AND(TbRegistroEntradas[[#This Row],[Data do Caixa Previsto]]<TODAY(),TbRegistroEntradas[[#This Row],[Data do Caixa Realizado]]=""),"Vencida","Não Vencida") -> Não Vencida | P5: =IF(TbRegistroEntradas[[#This Row],[Data da Competência]]=TbRegistroEntradas[[#This Row],[Data do Caixa Previsto]],"Vista","Prazo") -> Prazo | Q5: =IF(TbRegistroEntradas[[#This Row],[Data do Caixa Realizado]]<>"", IF(TbRegistroEntradas[[#This Row],[Data do Caixa Realizado]]>TbRegistroEntradas[[#This Row],[Data do Caixa Previsto]], TbRegistroEntradas[[#This Row],[Data do Caixa Realizado]]-TbRegistroEntradas[[#This Row],[Data do Caixa Previsto]], 0 ), IF(TODAY()>TbRegistroEntradas[[#This Row],[Data do Caixa Previsto]], TODAY()-TbRegistroEntradas[[#This Row],[Data do Caixa Previsto]], 0 ) ) -> 0
B6: 45564 | C6: 45521 | D6: 45558 | E6: Vendas de mercadorias | F6: Móveis | G6: NF8005 | H6: 2937 | I6: =IF(TbRegistroEntradas[[#This Row],[Data do Caixa Realizado]]="",0,MONTH(TbRegistroEntradas[[#This Row],[Data do Caixa Previsto]])) -> 9 | J6: =IF(TbRegistroEntradas[[#This Row],[Data do Caixa Realizado]]="",0,YEAR(TbRegistroEntradas[[#This Row],[Data do Caixa Realizado]])) -> 2024 | K6: =IF(TbRegistroEntradas[[#This Row],[Data da Competência]]="",0,MONTH(TbRegistroEntradas[[#This Row],[Data da Competência]])) -> 8 | L6: =IF(TbRegistroEntradas[[#This Row],[Data da Competência]]="",0,YEAR(TbRegistroEntradas[[#This Row],[Data da Competência]])) -> 2024 | M6: =IF(TbRegistroEntradas[[#This Row],[Data do Caixa Previsto]]="",0,MONTH(TbRegistroEntradas[[#This Row],[Data do Caixa Previsto]])) -> 9 | N6: =IF(TbRegistroEntradas[[#This Row],[Data do Caixa Previsto]]="",0,YEAR(TbRegistroEntradas[[#This Row],[Data do Caixa Previsto]])) -> 2024 | O6: =IF(AND(TbRegistroEntradas[[#This Row],[Data do Caixa Previsto]]<TODAY(),TbRegistroEntradas[[#This Row],[Data do Caixa Realizado]]=""),"Vencida","Não Vencida") -> Não Vencida | P6: =IF(TbRegistroEntradas[[#This Row],[Data da Competência]]=TbRegistroEntradas[[#This Row],[Data do Caixa Previsto]],"Vista","Prazo") -> Prazo | Q6: =IF(TbRegistroEntradas[[#This Row],[Data do Caixa Realizado]]<>"", IF(TbRegistroEntradas[[#This Row],[Data do Caixa Realizado]]>TbRegistroEntradas[[#This Row],[Data do Caixa Previsto]], TbRegistroEntradas[[#This Row],[Data do Caixa Realizado]]-TbRegistroEntradas[[#This Row],[Data do Caixa Previsto]], 0 ), IF(TODAY()>TbRegistroEntradas[[#This Row],[Data do Caixa Previsto]], TODAY()-TbRegistroEntradas[[#This Row],[Data do Caixa Previsto]], 0 ) ) -> 6
B7: 45577 | C7: 45526 | D7: 45577 | E7: Vendas de mercadorias | F7: Som e imagem | G7: NF5493 | H7: 807 | I7: =IF(TbRegistroEntradas[[#This Row],[Data do Caixa Realizado]]="",0,MONTH(TbRegistroEntradas[[#This Row],[Data do Caixa Previsto]])) -> 10 | J7: =IF(TbRegistroEntradas[[#This Row],[Data do Caixa Realizado]]="",0,YEAR(TbRegistroEntradas[[#This Row],[Data do Caixa Realizado]])) -> 2024 | K7: =IF(TbRegistroEntradas[[#This Row],[Data da Competência]]="",0,MONTH(TbRegistroEntradas[[#This Row],[Data da Competência]])) -> 8 | L7: =IF(TbRegistroEntradas[[#This Row],[Data da Competência]]="",0,YEAR(TbRegistroEntradas[[#This Row],[Data da Competência]])) -> 2024 | M7: =IF(TbRegistroEntradas[[#This Row],[Data do Caixa Previsto]]="",0,MONTH(TbRegistroEntradas[[#This Row],[Data do Caixa Previsto]])) -> 10 | N7: =IF(TbRegistroEntradas[[#This Row],[Data do Caixa Previsto]]="",0,YEAR(TbRegistroEntradas[[#This Row],[Data do Caixa Previsto]])) -> 2024 | O7: =IF(AND(TbRegistroEntradas[[#This Row],[Data do Caixa Previsto]]<TODAY(),TbRegistroEntradas[[#This Row],[Data do Caixa Realizado]]=""),"Vencida","Não Vencida") -> Não Vencida | P7: =IF(TbRegistroEntradas[[#This Row],[Data da Competência]]=TbRegistroEntradas[[#This Row],[Data do Caixa Previsto]],"Vista","Prazo") -> Prazo | Q7: =IF(TbRegistroEntradas[[#This Row],[Data do Caixa Realizado]]<>"", IF(TbRegistroEntradas[[#This Row],[Data do Caixa Realizado]]>TbRegistroEntradas[[#This Row],[Data do Caixa Previsto]], TbRegistroEntradas[[#This Row],[Data do Caixa Realizado]]-TbRegistroEntradas[[#This Row],[Data do Caixa Previsto]], 0 ), IF(TODAY()>TbRegistroEntradas[[#This Row],[Data do Caixa Previsto]], TODAY()-TbRegistroEntradas[[#This Row],[Data do Caixa Previsto]], 0 ) ) -> 0
B8: 45571 | C8: 45529 | D8: 45571 | E8: Vendas de mercadorias | F8: Informática | G8: NF7946 | H8: 2612 | I8: =IF(TbRegistroEntradas[[#This Row],[Data do Caixa Realizado]]="",0,MONTH(TbRegistroEntradas[[#This Row],[Data do Caixa Previsto]])) -> 10 | J8: =IF(TbRegistroEntradas[[#This Row],[Data do Caixa Realizado]]="",0,YEAR(TbRegistroEntradas[[#This Row],[Data do Caixa Realizado]])) -> 2024 | K8: =IF(TbRegistroEntradas[[#This Row],[Data da Competência]]="",0,MONTH(TbRegistroEntradas[[#This Row],[Data da Competência]])) -> 8 | L8: =IF(TbRegistroEntradas[[#This Row],[Data da Competência]]="",0,YEAR(TbRegistroEntradas[[#This Row],[Data da Competência]])) -> 2024 | M8: =IF(TbRegistroEntradas[[#This Row],[Data do Caixa Previsto]]="",0,MONTH(TbRegistroEntradas[[#This Row],[Data do Caixa Previsto]])) -> 10 | N8: =IF(TbRegistroEntradas[[#This Row],[Data do Caixa Previsto]]="",0,YEAR(TbRegistroEntradas[[#This Row],[Data do Caixa Previsto]])) -> 2024 | O8: =IF(AND(TbRegistroEntradas[[#This Row],[Data do Caixa Previsto]]<TODAY(),TbRegistroEntradas[[#This Row],[Data do Caixa Realizado]]=""),"Vencida","Não Vencida") -> Não Vencida | P8: =IF(TbRegistroEntradas[[#This Row],[Data da Competência]]=TbRegistroEntradas[[#This Row],[Data do Caixa Previsto]],"Vista","Prazo") -> Prazo | Q8: =IF(TbRegistroEntradas[[#This Row],[Data do Caixa Realizado]]<>"", IF(TbRegistroEntradas[[#This Row],[Data do Caixa Realizado]]>TbRegistroEntradas[[#This Row],[Data do Caixa Previsto]], TbRegistroEntradas[[#This Row],[Data do Caixa Realizado]]-TbRegistroEntradas[[#This Row],[Data do Caixa Previsto]], 0 ), IF(TODAY()>TbRegistroEntradas[[#This Row],[Data do Caixa Previsto]], TODAY()-TbRegistroEntradas[[#This Row],[Data do Caixa Previsto]], 0 ) ) -> 0
B9: 45611 | C9: 45531 | D9: 45587 | E9: Vendas de mercadorias | F9: Móveis | G9: NF8598 | H9: 2483 | I9: =IF(TbRegistroEntradas[[#This Row],[Data do Caixa Realizado]]="",0,MONTH(TbRegistroEntradas[[#This Row],[Data do Caixa Previsto]])) -> 10 | J9: =IF(TbRegistroEntradas[[#This Row],[Data do Caixa Realizado]]="",0,YEAR(TbRegistroEntradas[[#This Row],[Data do Caixa Realizado]])) -> 2024 | K9: =IF(TbRegistroEntradas[[#This Row],[Data da Competência]]="",0,MONTH(TbRegistroEntradas[[#This Row],[Data da Competência]])) -> 8 | L9: =IF(TbRegistroEntradas[[#This Row],[Data da Competência]]="",0,YEAR(TbRegistroEntradas[[#This Row],[Data da Competência]])) -> 2024 | M9: =IF(TbRegistroEntradas[[#This Row],[Data do Caixa Previsto]]="",0,MONTH(TbRegistroEntradas[[#This Row],[Data do Caixa Previsto]])) -> 10 | N9: =IF(TbRegistroEntradas[[#This Row],[Data do Caixa Previsto]]="",0,YEAR(TbRegistroEntradas[[#This Row],[Data do Caixa Previsto]])) -> 2024 | O9: =IF(AND(TbRegistroEntradas[[#This Row],[Data do Caixa Previsto]]<TODAY(),TbRegistroEntradas[[#This Row],[Data do Caixa Realizado]]=""),"Vencida","Não Vencida") -> Não Vencida | P9: =IF(TbRegistroEntradas[[#This Row],[Data da Competência]]=TbRegistroEntradas[[#This Row],[Data do Caixa Previsto]],"Vista","Prazo") -> Prazo | Q9: =IF(TbRegistroEntradas[[#This Row],[Data do Caixa Realizado]]<>"", IF(TbRegistroEntradas[[#This Row],[Data do Caixa Realizado]]>TbRegistroEntradas[[#This Row],[Data do Caixa Previsto]], TbRegistroEntradas[[#This Row],[Data do Caixa Realizado]]-TbRegistroEntradas[[#This Row],[Data do Caixa Previsto]], 0 ), IF(TODAY()>TbRegistroEntradas[[#This Row],[Data do Caixa Previsto]], TODAY()-TbRegistroEntradas[[#This Row],[Data do Caixa Previsto]], 0 ) ) -> 24
B10: 45644 | C10: 45536 | D10: 45566 | E10: Vendas de mercadorias | F10: Informática | G10: NF1535 | H10: 4387 | I10: =IF(TbRegistroEntradas[[#This Row],[Data do Caixa Realizado]]="",0,MONTH(TbRegistroEntradas[[#This Row],[Data do Caixa Previsto]])) -> 10 | J10: =IF(TbRegistroEntradas[[#This Row],[Data do Caixa Realizado]]="",0,YEAR(TbRegistroEntradas[[#This Row],[Data do Caixa Realizado]])) -> 2024 | K10: =IF(TbRegistroEntradas[[#This Row],[Data da Competência]]="",0,MONTH(TbRegistroEntradas[[#This Row],[Data da Competência]])) -> 9 | L10: =IF(TbRegistroEntradas[[#This Row],[Data da Competência]]="",0,YEAR(TbRegistroEntradas[[#This Row],[Data da Competência]])) -> 2024 | M10: =IF(TbRegistroEntradas[[#This Row],[Data do Caixa Previsto]]="",0,MONTH(TbRegistroEntradas[[#This Row],[Data do Caixa Previsto]])) -> 10 | N10: =IF(TbRegistroEntradas[[#This Row],[Data do Caixa Previsto]]="",0,YEAR(TbRegistroEntradas[[#This Row],[Data do Caixa Previsto]])) -> 2024 | O10: =IF(AND(TbRegistroEntradas[[#This Row],[Data do Caixa Previsto]]<TODAY(),TbRegistroEntradas[[#This Row],[Data do Caixa Realizado]]=""),"Vencida","Não Vencida") -> Não Vencida | P10: =IF(TbRegistroEntradas[[#This Row],[Data da Competência]]=TbRegistroEntradas[[#This Row],[Data do Caixa Previsto]],"Vista","Prazo") -> Prazo | Q10: =IF(TbRegistroEntradas[[#This Row],[Data do Caixa Realizado]]<>"", IF(TbRegistroEntradas[[#This Row],[Data do Caixa Realizado]]>TbRegistroEntradas[[#This Row],[Data do Caixa Previsto]], TbRegistroEntradas[[#This Row],[Data do Caixa Realizado]]-TbRegistroEntradas[[#This Row],[Data do Caixa Previsto]], 0 ), IF(TODAY()>TbRegistroEntradas[[#This Row],[Data do Caixa Previsto]], TODAY()-TbRegistroEntradas[[#This Row],[Data do Caixa Previsto]], 0 ) ) -> 78
B11: 45561 | C11: 45537 | D11: 45561 | E11: Vendas de mercadorias | F11: Móveis | G11: NF4333 | H11: 4268 | I11: =IF(TbRegistroEntradas[[#This Row],[Data do Caixa Realizado]]="",0,MONTH(TbRegistroEntradas[[#This Row],[Data do Caixa Previsto]])) -> 9 | J11: =IF(TbRegistroEntradas[[#This Row],[Data do Caixa Realizado]]="",0,YEAR(TbRegistroEntradas[[#This Row],[Data do Caixa Realizado]])) -> 2024 | K11: =IF(TbRegistroEntradas[[#This Row],[Data da Competência]]="",0,MONTH(TbRegistroEntradas[[#This Row],[Data da Competência]])) -> 9 | L11: =IF(TbRegistroEntradas[[#This Row],[Data da Competência]]="",0,YEAR(TbRegistroEntradas[[#This Row],[Data da Competência]])) -> 2024 | M11: =IF(TbRegistroEntradas[[#This Row],[Data do Caixa Previsto]]="",0,MONTH(TbRegistroEntradas[[#This Row],[Data do Caixa Previsto]])) -> 9 | N11: =IF(TbRegistroEntradas[[#This Row],[Data do Caixa Previsto]]="",0,YEAR(TbRegistroEntradas[[#This Row],[Data do Caixa Previsto]])) -> 2024 | O11: =IF(AND(TbRegistroEntradas[[#This Row],[Data do Caixa Previsto]]<TODAY(),TbRegistroEntradas[[#This Row],[Data do Caixa Realizado]]=""),"Vencida","Não Vencida") -> Não Vencida | P11: =IF(TbRegistroEntradas[[#This Row],[Data da Competência]]=TbRegistroEntradas[[#This Row],[Data do Caixa Previsto]],"Vista","Prazo") -> Prazo | Q11: =IF(TbRegistroEntradas[[#This Row],[Data do Caixa Realizado]]<>"", IF(TbRegistroEntradas[[#This Row],[Data do Caixa Realizado]]>TbRegistroEntradas[[#This Row],[Data do Caixa Previsto]], TbRegistroEntradas[[#This Row],[Data do Caixa Realizado]]-TbRegistroEntradas[[#This Row],[Data do Caixa Previsto]], 0 ), IF(TODAY()>TbRegistroEntradas[[#This Row],[Data do Caixa Previsto]], TODAY()-TbRegistroEntradas[[#This Row],[Data do Caixa Previsto]], 0 ) ) -> 0
B12: 45572 | C12: 45541 | D12: 45572 | E12: Vendas de mercadorias | F12: Móveis | G12: NF8091 | H12: 3761 | I12: =IF(TbRegistroEntradas[[#This Row],[Data do Caixa Realizado]]="",0,MONTH(TbRegistroEntradas[[#This Row],[Data do Caixa Previsto]])) -> 10 | J12: =IF(TbRegistroEntradas[[#This Row],[Data do Caixa Realizado]]="",0,YEAR(TbRegistroEntradas[[#This Row],[Data do Caixa Realizado]])) -> 2024 | K12: =IF(TbRegistroEntradas[[#This Row],[Data da Competência]]="",0,MONTH(TbRegistroEntradas[[#This Row],[Data da Competência]])) -> 9 | L12: =IF(TbRegistroEntradas[[#This Row],[Data da Competência]]="",0,YEAR(TbRegistroEntradas[[#This Row],[Data da Competência]])) -> 2024 | M12: =IF(TbRegistroEntradas[[#This Row],[Data do Caixa Previsto]]="",0,MONTH(TbRegistroEntradas[[#This Row],[Data do Caixa Previsto]])) -> 10 | N12: =IF(TbRegistroEntradas[[#This Row],[Data do Caixa Previsto]]="",0,YEAR(TbRegistroEntradas[[#This Row],[Data do Caixa Previsto]])) -> 2024 | O12: =IF(AND(TbRegistroEntradas[[#This Row],[Data do Caixa Previsto]]<TODAY(),TbRegistroEntradas[[#This Row],[Data do Caixa Realizado]]=""),"Vencida","Não Vencida") -> Não Vencida | P12: =IF(TbRegistroEntradas[[#This Row],[Data da Competência]]=TbRegistroEntradas[[#This Row],[Data do Caixa Previsto]],"Vista","Prazo") -> Prazo | Q12: =IF(TbRegistroEntradas[[#This Row],[Data do Caixa Realizado]]<>"", IF(TbRegistroEntradas[[#This Row],[Data do Caixa Realizado]]>TbRegistroEntradas[[#This Row],[Data do Caixa Previsto]], TbRegistroEntradas[[#This Row],[Data do Caixa Realizado]]-TbRegistroEntradas[[#This Row],[Data do Caixa Previsto]], 0 ), IF(TODAY()>TbRegistroEntradas[[#This Row],[Data do Caixa Previsto]], TODAY()-TbRegistroEntradas[[#This Row],[Data do Caixa Previsto]], 0 ) ) -> 0
C13: 45545 | D13: 45570 | E13: Vendas de mercadorias | F13: Móveis | G13: NF2421 | H13: 4983 | I13: =IF(TbRegistroEntradas[[#This Row],[Data do Caixa Realizado]]="",0,MONTH(TbRegistroEntradas[[#This Row],[Data do Caixa Previsto]])) -> 0 | J13: =IF(TbRegistroEntradas[[#This Row],[Data do Caixa Realizado]]="",0,YEAR(TbRegistroEntradas[[#This Row],[Data do Caixa Realizado]])) -> 0 | K13: =IF(TbRegistroEntradas[[#This Row],[Data da Competência]]="",0,MONTH(TbRegistroEntradas[[#This Row],[Data da Competência]])) -> 9 | L13: =IF(TbRegistroEntradas[[#This Row],[Data da Competência]]="",0,YEAR(TbRegistroEntradas[[#This Row],[Data da Competência]])) -> 2024 | M13: =IF(TbRegistroEntradas[[#This Row],[Data do Caixa Previsto]]="",0,MONTH(TbRegistroEntradas[[#This Row],[Data do Caixa Previsto]])) -> 10 | N13: =IF(TbRegistroEntradas[[#This Row],[Data do Caixa Previsto]]="",0,YEAR(TbRegistroEntradas[[#This Row],[Data do Caixa Previsto]])) -> 2024 | O13: =IF(AND(TbRegistroEntradas[[#This Row],[Data do Caixa Previsto]]<TODAY(),TbRegistroEntradas[[#This Row],[Data do Caixa Realizado]]=""),"Vencida","Não Vencida") -> Vencida | P13: =IF(TbRegistroEntradas[[#This Row],[Data da Competência]]=TbRegistroEntradas[[#This Row],[Data do Caixa Previsto]],"Vista","Prazo") -> Prazo | Q13: =IF(TbRegistroEntradas[[#This Row],[Data do Caixa Realizado]]<>"", IF(TbRegistroEntradas[[#This Row],[Data do Caixa Realizado]]>TbRegistroEntradas[[#This Row],[Data do Caixa Previsto]], TbRegistroEntradas[[#This Row],[Data do Caixa Realizado]]-TbRegistroEntradas[[#This Row],[Data do Caixa Previsto]], 0 ), IF(TODAY()>TbRegistroEntradas[[#This Row],[Data do Caixa Previsto]], TODAY()-TbRegistroEntradas[[#This Row],[Data do Caixa Previsto]], 0 ) ) -> 639
B14: 45554 | C14: 45547 | D14: 45554 | E14: Vendas de mercadorias | F14: Eletrodomésticos | G14: NF9787 | H14: 2502 | I14: =IF(TbRegistroEntradas[[#This Row],[Data do Caixa Realizado]]="",0,MONTH(TbRegistroEntradas[[#This Row],[Data do Caixa Previsto]])) -> 9 | J14: =IF(TbRegistroEntradas[[#This Row],[Data do Caixa Realizado]]="",0,YEAR(TbRegistroEntradas[[#This Row],[Data do Caixa Realizado]])) -> 2024 | K14: =IF(TbRegistroEntradas[[#This Row],[Data da Competência]]="",0,MONTH(TbRegistroEntradas[[#This Row],[Data da Competência]])) -> 9 | L14: =IF(TbRegistroEntradas[[#This Row],[Data da Competência]]="",0,YEAR(TbRegistroEntradas[[#This Row],[Data da Competência]])) -> 2024 | M14: =IF(TbRegistroEntradas[[#This Row],[Data do Caixa Previsto]]="",0,MONTH(TbRegistroEntradas[[#This Row],[Data do Caixa Previsto]])) -> 9 | N14: =IF(TbRegistroEntradas[[#This Row],[Data do Caixa Previsto]]="",0,YEAR(TbRegistroEntradas[[#This Row],[Data do Caixa Previsto]])) -> 2024 | O14: =IF(AND(TbRegistroEntradas[[#This Row],[Data do Caixa Previsto]]<TODAY(),TbRegistroEntradas[[#This Row],[Data do Caixa Realizado]]=""),"Vencida","Não Vencida") -> Não Vencida | P14: =IF(TbRegistroEntradas[[#This Row],[Data da Competência]]=TbRegistroEntradas[[#This Row],[Data do Caixa Previsto]],"Vista","Prazo") -> Prazo | Q14: =IF(TbRegistroEntradas[[#This Row],[Data do Caixa Realizado]]<>"", IF(TbRegistroEntradas[[#This Row],[Data do Caixa Realizado]]>TbRegistroEntradas[[#This Row],[Data do Caixa Previsto]], TbRegistroEntradas[[#This Row],[Data do Caixa Realizado]]-TbRegistroEntradas[[#This Row],[Data do Caixa Previsto]], 0 ), IF(TODAY()>TbRegistroEntradas[[#This Row],[Data do Caixa Previsto]], TODAY()-TbRegistroEntradas[[#This Row],[Data do Caixa Previsto]], 0 ) ) -> 0
B15: 45561 | C15: 45551 | D15: 45559 | E15: Vendas de mercadorias | F15: Móveis | G15: NF8674 | H15: 2337 | I15: =IF(TbRegistroEntradas[[#This Row],[Data do Caixa Realizado]]="",0,MONTH(TbRegistroEntradas[[#This Row],[Data do Caixa Previsto]])) -> 9 | J15: =IF(TbRegistroEntradas[[#This Row],[Data do Caixa Realizado]]="",0,YEAR(TbRegistroEntradas[[#This Row],[Data do Caixa Realizado]])) -> 2024 | K15: =IF(TbRegistroEntradas[[#This Row],[Data da Competência]]="",0,MONTH(TbRegistroEntradas[[#This Row],[Data da Competência]])) -> 9 | L15: =IF(TbRegistroEntradas[[#This Row],[Data da Competência]]="",0,YEAR(TbRegistroEntradas[[#This Row],[Data da Competência]])) -> 2024 | M15: =IF(TbRegistroEntradas[[#This Row],[Data do Caixa Previsto]]="",0,MONTH(TbRegistroEntradas[[#This Row],[Data do Caixa Previsto]])) -> 9 | N15: =IF(TbRegistroEntradas[[#This Row],[Data do Caixa Previsto]]="",0,YEAR(TbRegistroEntradas[[#This Row],[Data do Caixa Previsto]])) -> 2024 | O15: =IF(AND(TbRegistroEntradas[[#This Row],[Data do Caixa Previsto]]<TODAY(),TbRegistroEntradas[[#This Row],[Data do Caixa Realizado]]=""),"Vencida","Não Vencida") -> Não Vencida | P15: =IF(TbRegistroEntradas[[#This Row],[Data da Competência]]=TbRegistroEntradas[[#This Row],[Data do Caixa Previsto]],"Vista","Prazo") -> Prazo | Q15: =IF(TbRegistroEntradas[[#This Row],[Data do Caixa Realizado]]<>"", IF(TbRegistroEntradas[[#This Row],[Data do Caixa Realizado]]>TbRegistroEntradas[[#This Row],[Data do Caixa Previsto]], TbRegistroEntradas[[#This Row],[Data do Caixa Realizado]]-TbRegistroEntradas[[#This Row],[Data do Caixa Previsto]], 0 ), IF(TODAY()>TbRegistroEntradas[[#This Row],[Data do Caixa Previsto]], TODAY()-TbRegistroEntradas[[#This Row],[Data do Caixa Previsto]], 0 ) ) -> 2
B16: 45567 | C16: 45558 | D16: 45567 | E16: Vendas de mercadorias | F16: Livros | G16: NF5880 | H16: 3125 | I16: =IF(TbRegistroEntradas[[#This Row],[Data do Caixa Realizado]]="",0,MONTH(TbRegistroEntradas[[#This Row],[Data do Caixa Previsto]])) -> 10 | J16: =IF(TbRegistroEntradas[[#This Row],[Data do Caixa Realizado]]="",0,YEAR(TbRegistroEntradas[[#This Row],[Data do Caixa Realizado]])) -> 2024 | K16: =IF(TbRegistroEntradas[[#This Row],[Data da Competência]]="",0,MONTH(TbRegistroEntradas[[#This Row],[Data da Competência]])) -> 9 | L16: =IF(TbRegistroEntradas[[#This Row],[Data da Competência]]="",0,YEAR(TbRegistroEntradas[[#This Row],[Data da Competência]])) -> 2024 | M16: =IF(TbRegistroEntradas[[#This Row],[Data do Caixa Previsto]]="",0,MONTH(TbRegistroEntradas[[#This Row],[Data do Caixa Previsto]])) -> 10 | N16: =IF(TbRegistroEntradas[[#This Row],[Data do Caixa Previsto]]="",0,YEAR(TbRegistroEntradas[[#This Row],[Data do Caixa Previsto]])) -> 2024 | O16: =IF(AND(TbRegistroEntradas[[#This Row],[Data do Caixa Previsto]]<TODAY(),TbRegistroEntradas[[#This Row],[Data do Caixa Realizado]]=""),"Vencida","Não Vencida") -> Não Vencida | P16: =IF(TbRegistroEntradas[[#This Row],[Data da Competência]]=TbRegistroEntradas[[#This Row],[Data do Caixa Previsto]],"Vista","Prazo") -> Prazo | Q16: =IF(TbRegistroEntradas[[#This Row],[Data do Caixa Realizado]]<>"", IF(TbRegistroEntradas[[#This Row],[Data do Caixa Realizado]]>TbRegistroEntradas[[#This Row],[Data do Caixa Previsto]], TbRegistroEntradas[[#This Row],[Data do Caixa Realizado]]-TbRegistroEntradas[[#This Row],[Data do Caixa Previsto]], 0 ), IF(TODAY()>TbRegistroEntradas[[#This Row],[Data do Caixa Previsto]], TODAY()-TbRegistroEntradas[[#This Row],[Data do Caixa Previsto]], 0 ) ) -> 0
B17: 45613 | C17: 45561 | D17: 45613 | E17: Vendas de mercadorias | F17: Móveis | G17: NF2763 | H17: 1201 | I17: =IF(TbRegistroEntradas[[#This Row],[Data do Caixa Realizado]]="",0,MONTH(TbRegistroEntradas[[#This Row],[Data do Caixa Previsto]])) -> 11 | J17: =IF(TbRegistroEntradas[[#This Row],[Data do Caixa Realizado]]="",0,YEAR(TbRegistroEntradas[[#This Row],[Data do Caixa Realizado]])) -> 2024 | K17: =IF(TbRegistroEntradas[[#This Row],[Data da Competência]]="",0,MONTH(TbRegistroEntradas[[#This Row],[Data da Competência]])) -> 9 | L17: =IF(TbRegistroEntradas[[#This Row],[Data da Competência]]="",0,YEAR(TbRegistroEntradas[[#This Row],[Data da Competência]])) -> 2024 | M17: =IF(TbRegistroEntradas[[#This Row],[Data do Caixa Previsto]]="",0,MONTH(TbRegistroEntradas[[#This Row],[Data do Caixa Previsto]])) -> 11 | N17: =IF(TbRegistroEntradas[[#This Row],[Data do Caixa Previsto]]="",0,YEAR(TbRegistroEntradas[[#This Row],[Data do Caixa Previsto]])) -> 2024 | O17: =IF(AND(TbRegistroEntradas[[#This Row],[Data do Caixa Previsto]]<TODAY(),TbRegistroEntradas[[#This Row],[Data do Caixa Realizado]]=""),"Vencida","Não Vencida") -> Não Vencida | P17: =IF(TbRegistroEntradas[[#This Row],[Data da Competência]]=TbRegistroEntradas[[#This Row],[Data do Caixa Previsto]],"Vista","Prazo") -> Prazo | Q17: =IF(TbRegistroEntradas[[#This Row],[Data do Caixa Realizado]]<>"", IF(TbRegistroEntradas[[#This Row],[Data do Caixa Realizado]]>TbRegistroEntradas[[#This Row],[Data do Caixa Previsto]], TbRegistroEntradas[[#This Row],[Data do Caixa Realizado]]-TbRegistroEntradas[[#This Row],[Data do Caixa Previsto]], 0 ), IF(TODAY()>TbRegistroEntradas[[#This Row],[Data do Caixa Previsto]], TODAY()-TbRegistroEntradas[[#This Row],[Data do Caixa Previsto]], 0 ) ) -> 0
B18: 45590 | C18: 45562 | D18: 45575 | E18: Vendas de mercadorias | F18: Informática | G18: NF3303 | H18: 4380 | I18: =IF(TbRegistroEntradas[[#This Row],[Data do Caixa Realizado]]="",0,MONTH(TbRegistroEntradas[[#This Row],[Data do Caixa Previsto]])) -> 10 | J18: =IF(TbRegistroEntradas[[#This Row],[Data do Caixa Realizado]]="",0,YEAR(TbRegistroEntradas[[#This Row],[Data do Caixa Realizado]])) -> 2024 | K18: =IF(TbRegistroEntradas[[#This Row],[Data da Competência]]="",0,MONTH(TbRegistroEntradas[[#This Row],[Data da Competência]])) -> 9 | L18: =IF(TbRegistroEntradas[[#This Row],[Data da Competência]]="",0,YEAR(TbRegistroEntradas[[#This Row],[Data da Competência]])) -> 2024 | M18: =IF(TbRegistroEntradas[[#This Row],[Data do Caixa Previsto]]="",0,MONTH(TbRegistroEntradas[[#This Row],[Data do Caixa Previsto]])) -> 10 | N18: =IF(TbRegistroEntradas[[#This Row],[Data do Caixa Previsto]]="",0,YEAR(TbRegistroEntradas[[#This Row],[Data do Caixa Previsto]])) -> 2024 | O18: =IF(AND(TbRegistroEntradas[[#This Row],[Data do Caixa Previsto]]<TODAY(),TbRegistroEntradas[[#This Row],[Data do Caixa Realizado]]=""),"Vencida","Não Vencida") -> Não Vencida | P18: =IF(TbRegistroEntradas[[#This Row],[Data da Competência]]=TbRegistroEntradas[[#This Row],[Data do Caixa Previsto]],"Vista","Prazo") -> Prazo | Q18: =IF(TbRegistroEntradas[[#This Row],[Data do Caixa Realizado]]<>"", IF(TbRegistroEntradas[[#This Row],[Data do Caixa Realizado]]>TbRegistroEntradas[[#This Row],[Data do Caixa Previsto]], TbRegistroEntradas[[#This Row],[Data do Caixa Realizado]]-TbRegistroEntradas[[#This Row],[Data do Caixa Previsto]], 0 ), IF(TODAY()>TbRegistroEntradas[[#This Row],[Data do Caixa Previsto]], TODAY()-TbRegistroEntradas[[#This Row],[Data do Caixa Previsto]], 0 ) ) -> 15
B19: 45576 | C19: 45565 | D19: 45576 | E19: Vendas de mercadorias | F19: Livros | G19: NF3966 | H19: 919 | I19: =IF(TbRegistroEntradas[[#This Row],[Data do Caixa Realizado]]="",0,MONTH(TbRegistroEntradas[[#This Row],[Data do Caixa Previsto]])) -> 10 | J19: =IF(TbRegistroEntradas[[#This Row],[Data do Caixa Realizado]]="",0,YEAR(TbRegistroEntradas[[#This Row],[Data do Caixa Realizado]])) -> 2024 | K19: =IF(TbRegistroEntradas[[#This Row],[Data da Competência]]="",0,MONTH(TbRegistroEntradas[[#This Row],[Data da Competência]])) -> 9 | L19: =IF(TbRegistroEntradas[[#This Row],[Data da Competência]]="",0,YEAR(TbRegistroEntradas[[#This Row],[Data da Competência]])) -> 2024 | M19: =IF(TbRegistroEntradas[[#This Row],[Data do Caixa Previsto]]="",0,MONTH(TbRegistroEntradas[[#This Row],[Data do Caixa Previsto]])) -> 10 | N19: =IF(TbRegistroEntradas[[#This Row],[Data do Caixa Previsto]]="",0,YEAR(TbRegistroEntradas[[#This Row],[Data do Caixa Previsto]])) -> 2024 | O19: =IF(AND(TbRegistroEntradas[[#This Row],[Data do Caixa Previsto]]<TODAY(),TbRegistroEntradas[[#This Row],[Data do Caixa Realizado]]=""),"Vencida","Não Vencida") -> Não Vencida | P19: =IF(TbRegistroEntradas[[#This Row],[Data da Competência]]=TbRegistroEntradas[[#This Row],[Data do Caixa Previsto]],"Vista","Prazo") -> Prazo | Q19: =IF(TbRegistroEntradas[[#This Row],[Data do Caixa Realizado]]<>"", IF(TbRegistroEntradas[[#This Row],[Data do Caixa Realizado]]>TbRegistroEntradas[[#This Row],[Data do Caixa Previsto]], TbRegistroEntradas[[#This Row],[Data do Caixa Realizado]]-TbRegistroEntradas[[#This Row],[Data do Caixa Previsto]], 0 ), IF(TODAY()>TbRegistroEntradas[[#This Row],[Data do Caixa Previsto]], TODAY()-TbRegistroEntradas[[#This Row],[Data do Caixa Previsto]], 0 ) ) -> 0
B20: 45582 | C20: 45569 | D20: 45582 | E20: Vendas de mercadorias | F20: Som e imagem | G20: NF6107 | H20: 4590 | I20: =IF(TbRegistroEntradas[[#This Row],[Data do Caixa Realizado]]="",0,MONTH(TbRegistroEntradas[[#This Row],[Data do Caixa Previsto]])) -> 10 | J20: =IF(TbRegistroEntradas[[#This Row],[Data do Caixa Realizado]]="",0,YEAR(TbRegistroEntradas[[#This Row],[Data do Caixa Realizado]])) -> 2024 | K20: =IF(TbRegistroEntradas[[#This Row],[Data da Competência]]="",0,MONTH(TbRegistroEntradas[[#This Row],[Data da Competência]])) -> 10 | L20: =IF(TbRegistroEntradas[[#This Row],[Data da Competência]]="",0,YEAR(TbRegistroEntradas[[#This Row],[Data da Competência]])) -> 2024 | M20: =IF(TbRegistroEntradas[[#This Row],[Data do Caixa Previsto]]="",0,MONTH(TbRegistroEntradas[[#This Row],[Data do Caixa Previsto]])) -> 10 | N20: =IF(TbRegistroEntradas[[#This Row],[Data do Caixa Previsto]]="",0,YEAR(TbRegistroEntradas[[#This Row],[Data do Caixa Previsto]])) -> 2024 | O20: =IF(AND(TbRegistroEntradas[[#This Row],[Data do Caixa Previsto]]<TODAY(),TbRegistroEntradas[[#This Row],[Data do Caixa Realizado]]=""),"Vencida","Não Vencida") -> Não Vencida | P20: =IF(TbRegistroEntradas[[#This Row],[Data da Competência]]=TbRegistroEntradas[[#This Row],[Data do Caixa Previsto]],"Vista","Prazo") -> Prazo | Q20: =IF(TbRegistroEntradas[[#This Row],[Data do Caixa Realizado]]<>"", IF(TbRegistroEntradas[[#This Row],[Data do Caixa Realizado]]>TbRegistroEntradas[[#This Row],[Data do Caixa Previsto]], TbRegistroEntradas[[#This Row],[Data do Caixa Realizado]]-TbRegistroEntradas[[#This Row],[Data do Caixa Previsto]], 0 ), IF(TODAY()>TbRegistroEntradas[[#This Row],[Data do Caixa Previsto]], TODAY()-TbRegistroEntradas[[#This Row],[Data do Caixa Previsto]], 0 ) ) -> 0
B21: 45609 | C21: 45572 | D21: 45609 | E21: Vendas de mercadorias | F21: Eletrodomésticos | G21: NF4832 | H21: 1958 | I21: =IF(TbRegistroEntradas[[#This Row],[Data do Caixa Realizado]]="",0,MONTH(TbRegistroEntradas[[#This Row],[Data do Caixa Previsto]])) -> 11 | J21: =IF(TbRegistroEntradas[[#This Row],[Data do Caixa Realizado]]="",0,YEAR(TbRegistroEntradas[[#This Row],[Data do Caixa Realizado]])) -> 2024 | K21: =IF(TbRegistroEntradas[[#This Row],[Data da Competência]]="",0,MONTH(TbRegistroEntradas[[#This Row],[Data da Competência]])) -> 10 | L21: =IF(TbRegistroEntradas[[#This Row],[Data da Competência]]="",0,YEAR(TbRegistroEntradas[[#This Row],[Data da Competência]])) -> 2024 | M21: =IF(TbRegistroEntradas[[#This Row],[Data do Caixa Previsto]]="",0,MONTH(TbRegistroEntradas[[#This Row],[Data do Caixa Previsto]])) -> 11 | N21: =IF(TbRegistroEntradas[[#This Row],[Data do Caixa Previsto]]="",0,YEAR(TbRegistroEntradas[[#This Row],[Data do Caixa Previsto]])) -> 2024 | O21: =IF(AND(TbRegistroEntradas[[#This Row],[Data do Caixa Previsto]]<TODAY(),TbRegistroEntradas[[#This Row],[Data do Caixa Realizado]]=""),"Vencida","Não Vencida") -> Não Vencida | P21: =IF(TbRegistroEntradas[[#This Row],[Data da Competência]]=TbRegistroEntradas[[#This Row],[Data do Caixa Previsto]],"Vista","Prazo") -> Prazo | Q21: =IF(TbRegistroEntradas[[#This Row],[Data do Caixa Realizado]]<>"", IF(TbRegistroEntradas[[#This Row],[Data do Caixa Realizado]]>TbRegistroEntradas[[#This Row],[Data do Caixa Previsto]], TbRegistroEntradas[[#This Row],[Data do Caixa Realizado]]-TbRegistroEntradas[[#This Row],[Data do Caixa Previsto]], 0 ), IF(TODAY()>TbRegistroEntradas[[#This Row],[Data do Caixa Previsto]], TODAY()-TbRegistroEntradas[[#This Row],[Data do Caixa Previsto]], 0 ) ) -> 0
C22: 45574 | D22: 45600 | E22: Vendas de mercadorias | F22: Informática | G22: NF5012 | H22: 1171 | I22: =IF(TbRegistroEntradas[[#This Row],[Data do Caixa Realizado]]="",0,MONTH(TbRegistroEntradas[[#This Row],[Data do Caixa Previsto]])) -> 0 | J22: =IF(TbRegistroEntradas[[#This Row],[Data do Caixa Realizado]]="",0,YEAR(TbRegistroEntradas[[#This Row],[Data do Caixa Realizado]])) -> 0 | K22: =IF(TbRegistroEntradas[[#This Row],[Data da Competência]]="",0,MONTH(TbRegistroEntradas[[#This Row],[Data da Competência]])) -> 10 | L22: =IF(TbRegistroEntradas[[#This Row],[Data da Competência]]="",0,YEAR(TbRegistroEntradas[[#This Row],[Data da Competência]])) -> 2024 | M22: =IF(TbRegistroEntradas[[#This Row],[Data do Caixa Previsto]]="",0,MONTH(TbRegistroEntradas[[#This Row],[Data do Caixa Previsto]])) -> 11 | N22: =IF(TbRegistroEntradas[[#This Row],[Data do Caixa Previsto]]="",0,YEAR(TbRegistroEntradas[[#This Row],[Data do Caixa Previsto]])) -> 2024 | O22: =IF(AND(TbRegistroEntradas[[#This Row],[Data do Caixa Previsto]]<TODAY(),TbRegistroEntradas[[#This Row],[Data do Caixa Realizado]]=""),"Vencida","Não Vencida") -> Vencida | P22: =IF(TbRegistroEntradas[[#This Row],[Data da Competência]]=TbRegistroEntradas[[#This Row],[Data do Caixa Previsto]],"Vista","Prazo") -> Prazo | Q22: =IF(TbRegistroEntradas[[#This Row],[Data do Caixa Realizado]]<>"", IF(TbRegistroEntradas[[#This Row],[Data do Caixa Realizado]]>TbRegistroEntradas[[#This Row],[Data do Caixa Previsto]], TbRegistroEntradas[[#This Row],[Data do Caixa Realizado]]-TbRegistroEntradas[[#This Row],[Data do Caixa Previsto]], 0 ), IF(TODAY()>TbRegistroEntradas[[#This Row],[Data do Caixa Previsto]], TODAY()-TbRegistroEntradas[[#This Row],[Data do Caixa Previsto]], 0 ) ) -> 609
B23: 45691 | C23: 45576 | D23: 45617 | E23: Vendas de mercadorias | F23: Móveis | G23: NF7669 | H23: 2587 | I23: =IF(TbRegistroEntradas[[#This Row],[Data do Caixa Realizado]]="",0,MONTH(TbRegistroEntradas[[#This Row],[Data do Caixa Previsto]])) -> 11 | J23: =IF(TbRegistroEntradas[[#This Row],[Data do Caixa Realizado]]="",0,YEAR(TbRegistroEntradas[[#This Row],[Data do Caixa Realizado]])) -> 2025 | K23: =IF(TbRegistroEntradas[[#This Row],[Data da Competência]]="",0,MONTH(TbRegistroEntradas[[#This Row],[Data da Competência]])) -> 10 | L23: =IF(TbRegistroEntradas[[#This Row],[Data da Competência]]="",0,YEAR(TbRegistroEntradas[[#This Row],[Data da Competência]])) -> 2024 | M23: =IF(TbRegistroEntradas[[#This Row],[Data do Caixa Previsto]]="",0,MONTH(TbRegistroEntradas[[#This Row],[Data do Caixa Previsto]])) -> 11 | N23: =IF(TbRegistroEntradas[[#This Row],[Data do Caixa Previsto]]="",0,YEAR(TbRegistroEntradas[[#This Row],[Data do Caixa Previsto]])) -> 2024 | O23: =IF(AND(TbRegistroEntradas[[#This Row],[Data do Caixa Previsto]]<TODAY(),TbRegistroEntradas[[#This Row],[Data do Caixa Realizado]]=""),"Vencida","Não Vencida") -> Não Vencida | P23: =IF(TbRegistroEntradas[[#This Row],[Data da Competência]]=TbRegistroEntradas[[#This Row],[Data do Caixa Previsto]],"Vista","Prazo") -> Prazo | Q23: =IF(TbRegistroEntradas[[#This Row],[Data do Caixa Realizado]]<>"", IF(TbRegistroEntradas[[#This Row],[Data do Caixa Realizado]]>TbRegistroEntradas[[#This Row],[Data do Caixa Previsto]], TbRegistroEntradas[[#This Row],[Data do Caixa Realizado]]-TbRegistroEntradas[[#This Row],[Data do Caixa Previsto]], 0 ), IF(TODAY()>TbRegistroEntradas[[#This Row],[Data do Caixa Previsto]], TODAY()-TbRegistroEntradas[[#This Row],[Data do Caixa Previsto]], 0 ) ) -> 74
B24: 45602 | C24: 45580 | D24: 45602 | E24: Vendas de mercadorias | F24: Móveis | G24: NF7663 | H24: 3425 | I24: =IF(TbRegistroEntradas[[#This Row],[Data do Caixa Realizado]]="",0,MONTH(TbRegistroEntradas[[#This Row],[Data do Caixa Previsto]])) -> 11 | J24: =IF(TbRegistroEntradas[[#This Row],[Data do Caixa Realizado]]="",0,YEAR(TbRegistroEntradas[[#This Row],[Data do Caixa Realizado]])) -> 2024 | K24: =IF(TbRegistroEntradas[[#This Row],[Data da Competência]]="",0,MONTH(TbRegistroEntradas[[#This Row],[Data da Competência]])) -> 10 | L24: =IF(TbRegistroEntradas[[#This Row],[Data da Competência]]="",0,YEAR(TbRegistroEntradas[[#This Row],[Data da Competência]])) -> 2024 | M24: =IF(TbRegistroEntradas[[#This Row],[Data do Caixa Previsto]]="",0,MONTH(TbRegistroEntradas[[#This Row],[Data do Caixa Previsto]])) -> 11 | N24: =IF(TbRegistroEntradas[[#This Row],[Data do Caixa Previsto]]="",0,YEAR(TbRegistroEntradas[[#This Row],[Data do Caixa Previsto]])) -> 2024 | O24: =IF(AND(TbRegistroEntradas[[#This Row],[Data do Caixa Previsto]]<TODAY(),TbRegistroEntradas[[#This Row],[Data do Caixa Realizado]]=""),"Vencida","Não Vencida") -> Não Vencida | P24: =IF(TbRegistroEntradas[[#This Row],[Data da Competência]]=TbRegistroEntradas[[#This Row],[Data do Caixa Previsto]],"Vista","Prazo") -> Prazo | Q24: =IF(TbRegistroEntradas[[#This Row],[Data do Caixa Realizado]]<>"", IF(TbRegistroEntradas[[#This Row],[Data do Caixa Realizado]]>TbRegistroEntradas[[#This Row],[Data do Caixa Previsto]], TbRegistroEntradas[[#This Row],[Data do Caixa Realizado]]-TbRegistroEntradas[[#This Row],[Data do Caixa Previsto]], 0 ), IF(TODAY()>TbRegistroEntradas[[#This Row],[Data do Caixa Previsto]], TODAY()-TbRegistroEntradas[[#This Row],[Data do Caixa Previsto]], 0 ) ) -> 0
B25: 45614 | C25: 45583 | D25: 45614 | E25: Vendas de mercadorias | F25: Som e imagem | G25: NF4063 | H25: 4454 | I25: =IF(TbRegistroEntradas[[#This Row],[Data do Caixa Realizado]]="",0,MONTH(TbRegistroEntradas[[#This Row],[Data do Caixa Previsto]])) -> 11 | J25: =IF(TbRegistroEntradas[[#This Row],[Data do Caixa Realizado]]="",0,YEAR(TbRegistroEntradas[[#This Row],[Data do Caixa Realizado]])) -> 2024 | K25: =IF(TbRegistroEntradas[[#This Row],[Data da Competência]]="",0,MONTH(TbRegistroEntradas[[#This Row],[Data da Competência]])) -> 10 | L25: =IF(TbRegistroEntradas[[#This Row],[Data da Competência]]="",0,YEAR(TbRegistroEntradas[[#This Row],[Data da Competência]])) -> 2024 | M25: =IF(TbRegistroEntradas[[#This Row],[Data do Caixa Previsto]]="",0,MONTH(TbRegistroEntradas[[#This Row],[Data do Caixa Previsto]])) -> 11 | N25: =IF(TbRegistroEntradas[[#This Row],[Data do Caixa Previsto]]="",0,YEAR(TbRegistroEntradas[[#This Row],[Data do Caixa Previsto]])) -> 2024 | O25: =IF(AND(TbRegistroEntradas[[#This Row],[Data do Caixa Previsto]]<TODAY(),TbRegistroEntradas[[#This Row],[Data do Caixa Realizado]]=""),"Vencida","Não Vencida") -> Não Vencida | P25: =IF(TbRegistroEntradas[[#This Row],[Data da Competência]]=TbRegistroEntradas[[#This Row],[Data do Caixa Previsto]],"Vista","Prazo") -> Prazo | Q25: =IF(TbRegistroEntradas[[#This Row],[Data do Caixa Realizado]]<>"", IF(TbRegistroEntradas[[#This Row],[Data do Caixa Realizado]]>TbRegistroEntradas[[#This Row],[Data do Caixa Previsto]], TbRegistroEntradas[[#This Row],[Data do Caixa Realizado]]-TbRegistroEntradas[[#This Row],[Data do Caixa Previsto]], 0 ), IF(TODAY()>TbRegistroEntradas[[#This Row],[Data do Caixa Previsto]], TODAY()-TbRegistroEntradas[[#This Row],[Data do Caixa Previsto]], 0 ) ) -> 0
B26: 45594 | C26: 45587 | D26: 45594 | E26: Vendas de mercadorias | F26: Informática | G26: NF4290 | H26: 2134 | I26: =IF(TbRegistroEntradas[[#This Row],[Data do Caixa Realizado]]="",0,MONTH(TbRegistroEntradas[[#This Row],[Data do Caixa Previsto]])) -> 10 | J26: =IF(TbRegistroEntradas[[#This Row],[Data do Caixa Realizado]]="",0,YEAR(TbRegistroEntradas[[#This Row],[Data do Caixa Realizado]])) -> 2024 | K26: =IF(TbRegistroEntradas[[#This Row],[Data da Competência]]="",0,MONTH(TbRegistroEntradas[[#This Row],[Data da Competência]])) -> 10 | L26: =IF(TbRegistroEntradas[[#This Row],[Data da Competência]]="",0,YEAR(TbRegistroEntradas[[#This Row],[Data da Competência]])) -> 2024 | M26: =IF(TbRegistroEntradas[[#This Row],[Data do Caixa Previsto]]="",0,MONTH(TbRegistroEntradas[[#This Row],[Data do Caixa Previsto]])) -> 10 | N26: =IF(TbRegistroEntradas[[#This Row],[Data do Caixa Previsto]]="",0,YEAR(TbRegistroEntradas[[#This Row],[Data do Caixa Previsto]])) -> 2024 | O26: =IF(AND(TbRegistroEntradas[[#This Row],[Data do Caixa Previsto]]<TODAY(),TbRegistroEntradas[[#This Row],[Data do Caixa Realizado]]=""),"Vencida","Não Vencida") -> Não Vencida | P26: =IF(TbRegistroEntradas[[#This Row],[Data da Competência]]=TbRegistroEntradas[[#This Row],[Data do Caixa Previsto]],"Vista","Prazo") -> Prazo | Q26: =IF(TbRegistroEntradas[[#This Row],[Data do Caixa Realizado]]<>"", IF(TbRegistroEntradas[[#This Row],[Data do Caixa Realizado]]>TbRegistroEntradas[[#This Row],[Data do Caixa Previsto]], TbRegistroEntradas[[#This Row],[Data do Caixa Realizado]]-TbRegistroEntradas[[#This Row],[Data do Caixa Previsto]], 0 ), IF(TODAY()>TbRegistroEntradas[[#This Row],[Data do Caixa Previsto]], TODAY()-TbRegistroEntradas[[#This Row],[Data do Caixa Previsto]], 0 ) ) -> 0
B27: 45643 | C27: 45589 | D27: 45615 | E27: Vendas de mercadorias | F27: Eletrodomésticos | G27: NF7319 | H27: 257 | I27: =IF(TbRegistroEntradas[[#This Row],[Data do Caixa Realizado]]="",0,MONTH(TbRegistroEntradas[[#This Row],[Data do Caixa Previsto]])) -> 11 | J27: =IF(TbRegistroEntradas[[#This Row],[Data do Caixa Realizado]]="",0,YEAR(TbRegistroEntradas[[#This Row],[Data do Caixa Realizado]])) -> 2024 | K27: =IF(TbRegistroEntradas[[#This Row],[Data da Competência]]="",0,MONTH(TbRegistroEntradas[[#This Row],[Data da Competência]])) -> 10 | L27: =IF(TbRegistroEntradas[[#This Row],[Data da Competência]]="",0,YEAR(TbRegistroEntradas[[#This Row],[Data da Competência]])) -> 2024 | M27: =IF(TbRegistroEntradas[[#This Row],[Data do Caixa Previsto]]="",0,MONTH(TbRegistroEntradas[[#This Row],[Data do Caixa Previsto]])) -> 11 | N27: =IF(TbRegistroEntradas[[#This Row],[Data do Caixa Previsto]]="",0,YEAR(TbRegistroEntradas[[#This Row],[Data do Caixa Previsto]])) -> 2024 | O27: =IF(AND(TbRegistroEntradas[[#This Row],[Data do Caixa Previsto]]<TODAY(),TbRegistroEntradas[[#This Row],[Data do Caixa Realizado]]=""),"Vencida","Não Vencida") -> Não Vencida | P27: =IF(TbRegistroEntradas[[#This Row],[Data da Competência]]=TbRegistroEntradas[[#This Row],[Data do Caixa Previsto]],"Vista","Prazo") -> Prazo | Q27: =IF(TbRegistroEntradas[[#This Row],[Data do Caixa Realizado]]<>"", IF(TbRegistroEntradas[[#This Row],[Data do Caixa Realizado]]>TbRegistroEntradas[[#This Row],[Data do Caixa Previsto]], TbRegistroEntradas[[#This Row],[Data do Caixa Realizado]]-TbRegistroEntradas[[#This Row],[Data do Caixa Previsto]], 0 ), IF(TODAY()>TbRegistroEntradas[[#This Row],[Data do Caixa Previsto]], TODAY()-TbRegistroEntradas[[#This Row],[Data do Caixa Previsto]], 0 ) ) -> 28
B28: 45625 | C28: 45589 | D28: 45625 | E28: Vendas de mercadorias | F28: Livros | G28: NF7020 | H28: 2019 | I28: =IF(TbRegistroEntradas[[#This Row],[Data do Caixa Realizado]]="",0,MONTH(TbRegistroEntradas[[#This Row],[Data do Caixa Previsto]])) -> 11 | J28: =IF(TbRegistroEntradas[[#This Row],[Data do Caixa Realizado]]="",0,YEAR(TbRegistroEntradas[[#This Row],[Data do Caixa Realizado]])) -> 2024 | K28: =IF(TbRegistroEntradas[[#This Row],[Data da Competência]]="",0,MONTH(TbRegistroEntradas[[#This Row],[Data da Competência]])) -> 10 | L28: =IF(TbRegistroEntradas[[#This Row],[Data da Competência]]="",0,YEAR(TbRegistroEntradas[[#This Row],[Data da Competência]])) -> 2024 | M28: =IF(TbRegistroEntradas[[#This Row],[Data do Caixa Previsto]]="",0,MONTH(TbRegistroEntradas[[#This Row],[Data do Caixa Previsto]])) -> 11 | N28: =IF(TbRegistroEntradas[[#This Row],[Data do Caixa Previsto]]="",0,YEAR(TbRegistroEntradas[[#This Row],[Data do Caixa Previsto]])) -> 2024 | O28: =IF(AND(TbRegistroEntradas[[#This Row],[Data do Caixa Previsto]]<TODAY(),TbRegistroEntradas[[#This Row],[Data do Caixa Realizado]]=""),"Vencida","Não Vencida") -> Não Vencida | P28: =IF(TbRegistroEntradas[[#This Row],[Data da Competência]]=TbRegistroEntradas[[#This Row],[Data do Caixa Previsto]],"Vista","Prazo") -> Prazo | Q28: =IF(TbRegistroEntradas[[#This Row],[Data do Caixa Realizado]]<>"", IF(TbRegistroEntradas[[#This Row],[Data do Caixa Realizado]]>TbRegistroEntradas[[#This Row],[Data do Caixa Previsto]], TbRegistroEntradas[[#This Row],[Data do Caixa Realizado]]-TbRegistroEntradas[[#This Row],[Data do Caixa Previsto]], 0 ), IF(TODAY()>TbRegistroEntradas[[#This Row],[Data do Caixa Previsto]], TODAY()-TbRegistroEntradas[[#This Row],[Data do Caixa Previsto]], 0 ) ) -> 0
B29: 45648 | C29: 45591 | D29: 45648 | E29: Vendas de mercadorias | F29: Móveis | G29: NF7221 | H29: 3696 | I29: =IF(TbRegistroEntradas[[#This Row],[Data do Caixa Realizado]]="",0,MONTH(TbRegistroEntradas[[#This Row],[Data do Caixa Previsto]])) -> 12 | J29: =IF(TbRegistroEntradas[[#This Row],[Data do Caixa Realizado]]="",0,YEAR(TbRegistroEntradas[[#This Row],[Data do Caixa Realizado]])) -> 2024 | K29: =IF(TbRegistroEntradas[[#This Row],[Data da Competência]]="",0,MONTH(TbRegistroEntradas[[#This Row],[Data da Competência]])) -> 10 | L29: =IF(TbRegistroEntradas[[#This Row],[Data da Competência]]="",0,YEAR(TbRegistroEntradas[[#This Row],[Data da Competência]])) -> 2024 | M29: =IF(TbRegistroEntradas[[#This Row],[Data do Caixa Previsto]]="",0,MONTH(TbRegistroEntradas[[#This Row],[Data do Caixa Previsto]])) -> 12 | N29: =IF(TbRegistroEntradas[[#This Row],[Data do Caixa Previsto]]="",0,YEAR(TbRegistroEntradas[[#This Row],[Data do Caixa Previsto]])) -> 2024 | O29: =IF(AND(TbRegistroEntradas[[#This Row],[Data do Caixa Previsto]]<TODAY(),TbRegistroEntradas[[#This Row],[Data do Caixa Realizado]]=""),"Vencida","Não Vencida") -> Não Vencida | P29: =IF(TbRegistroEntradas[[#This Row],[Data da Competência]]=TbRegistroEntradas[[#This Row],[Data do Caixa Previsto]],"Vista","Prazo") -> Prazo | Q29: =IF(TbRegistroEntradas[[#This Row],[Data do Caixa Realizado]]<>"", IF(TbRegistroEntradas[[#This Row],[Data do Caixa Realizado]]>TbRegistroEntradas[[#This Row],[Data do Caixa Previsto]], TbRegistroEntradas[[#This Row],[Data do Caixa Realizado]]-TbRegistroEntradas[[#This Row],[Data do Caixa Previsto]], 0 ), IF(TODAY()>TbRegistroEntradas[[#This Row],[Data do Caixa Previsto]], TODAY()-TbRegistroEntradas[[#This Row],[Data do Caixa Previsto]], 0 ) ) -> 0
B30: 45609 | C30: 45595 | D30: 45609 | E30: Vendas de mercadorias | F30: Livros | G30: NF5004 | H30: 4446 | I30: =IF(TbRegistroEntradas[[#This Row],[Data do Caixa Realizado]]="",0,MONTH(TbRegistroEntradas[[#This Row],[Data do Caixa Previsto]])) -> 11 | J30: =IF(TbRegistroEntradas[[#This Row],[Data do Caixa Realizado]]="",0,YEAR(TbRegistroEntradas[[#This Row],[Data do Caixa Realizado]])) -> 2024 | K30: =IF(TbRegistroEntradas[[#This Row],[Data da Competência]]="",0,MONTH(TbRegistroEntradas[[#This Row],[Data da Competência]])) -> 10 | L30: =IF(TbRegistroEntradas[[#This Row],[Data da Competência]]="",0,YEAR(TbRegistroEntradas[[#This Row],[Data da Competência]])) -> 2024 | M30: =IF(TbRegistroEntradas[[#This Row],[Data do Caixa Previsto]]="",0,MONTH(TbRegistroEntradas[[#This Row],[Data do Caixa Previsto]])) -> 11 | N30: =IF(TbRegistroEntradas[[#This Row],[Data do Caixa Previsto]]="",0,YEAR(TbRegistroEntradas[[#This Row],[Data do Caixa Previsto]])) -> 2024 | O30: =IF(AND(TbRegistroEntradas[[#This Row],[Data do Caixa Previsto]]<TODAY(),TbRegistroEntradas[[#This Row],[Data do Caixa Realizado]]=""),"Vencida","Não Vencida") -> Não Vencida | P30: =IF(TbRegistroEntradas[[#This Row],[Data da Competência]]=TbRegistroEntradas[[#This Row],[Data do Caixa Previsto]],"Vista","Prazo") -> Prazo | Q30: =IF(TbRegistroEntradas[[#This Row],[Data do Caixa Realizado]]<>"", IF(TbRegistroEntradas[[#This Row],[Data do Caixa Realizado]]>TbRegistroEntradas[[#This Row],[Data do Caixa Previsto]], TbRegistroEntradas[[#This Row],[Data do Caixa Realizado]]-TbRegistroEntradas[[#This Row],[Data do Caixa Previsto]], 0 ), IF(TODAY()>TbRegistroEntradas[[#This Row],[Data do Caixa Previsto]], TODAY()-TbRegistroEntradas[[#This Row],[Data do Caixa Previsto]], 0 ) ) -> 0
B31: 45614 | C31: 45597 | D31: 45614 | E31: Vendas de mercadorias | F31: Livros | G31: NF8690 | H31: 1445 | I31: =IF(TbRegistroEntradas[[#This Row],[Data do Caixa Realizado]]="",0,MONTH(TbRegistroEntradas[[#This Row],[Data do Caixa Previsto]])) -> 11 | J31: =IF(TbRegistroEntradas[[#This Row],[Data do Caixa Realizado]]="",0,YEAR(TbRegistroEntradas[[#This Row],[Data do Caixa Realizado]])) -> 2024 | K31: =IF(TbRegistroEntradas[[#This Row],[Data da Competência]]="",0,MONTH(TbRegistroEntradas[[#This Row],[Data da Competência]])) -> 11 | L31: =IF(TbRegistroEntradas[[#This Row],[Data da Competência]]="",0,YEAR(TbRegistroEntradas[[#This Row],[Data da Competência]])) -> 2024 | M31: =IF(TbRegistroEntradas[[#This Row],[Data do Caixa Previsto]]="",0,MONTH(TbRegistroEntradas[[#This Row],[Data do Caixa Previsto]])) -> 11 | N31: =IF(TbRegistroEntradas[[#This Row],[Data do Caixa Previsto]]="",0,YEAR(TbRegistroEntradas[[#This Row],[Data do Caixa Previsto]])) -> 2024 | O31: =IF(AND(TbRegistroEntradas[[#This Row],[Data do Caixa Previsto]]<TODAY(),TbRegistroEntradas[[#This Row],[Data do Caixa Realizado]]=""),"Vencida","Não Vencida") -> Não Vencida | P31: =IF(TbRegistroEntradas[[#This Row],[Data da Competência]]=TbRegistroEntradas[[#This Row],[Data do Caixa Previsto]],"Vista","Prazo") -> Prazo | Q31: =IF(TbRegistroEntradas[[#This Row],[Data do Caixa Realizado]]<>"", IF(TbRegistroEntradas[[#This Row],[Data do Caixa Realizado]]>TbRegistroEntradas[[#This Row],[Data do Caixa Previsto]], TbRegistroEntradas[[#This Row],[Data do Caixa Realizado]]-TbRegistroEntradas[[#This Row],[Data do Caixa Previsto]], 0 ), IF(TODAY()>TbRegistroEntradas[[#This Row],[Data do Caixa Previsto]], TODAY()-TbRegistroEntradas[[#This Row],[Data do Caixa Previsto]], 0 ) ) -> 0
B32: 45639 | C32: 45600 | D32: 45625 | E32: Vendas de mercadorias | F32: Informática | G32: NF3424 | H32: 3559 | I32: =IF(TbRegistroEntradas[[#This Row],[Data do Caixa Realizado]]="",0,MONTH(TbRegistroEntradas[[#This Row],[Data do Caixa Previsto]])) -> 11 | J32: =IF(TbRegistroEntradas[[#This Row],[Data do Caixa Realizado]]="",0,YEAR(TbRegistroEntradas[[#This Row],[Data do Caixa Realizado]])) -> 2024 | K32: =IF(TbRegistroEntradas[[#This Row],[Data da Competência]]="",0,MONTH(TbRegistroEntradas[[#This Row],[Data da Competência]])) -> 11 | L32: =IF(TbRegistroEntradas[[#This Row],[Data da Competência]]="",0,YEAR(TbRegistroEntradas[[#This Row],[Data da Competência]])) -> 2024 | M32: =IF(TbRegistroEntradas[[#This Row],[Data do Caixa Previsto]]="",0,MONTH(TbRegistroEntradas[[#This Row],[Data do Caixa Previsto]])) -> 11 | N32: =IF(TbRegistroEntradas[[#This Row],[Data do Caixa Previsto]]="",0,YEAR(TbRegistroEntradas[[#This Row],[Data do Caixa Previsto]])) -> 2024 | O32: =IF(AND(TbRegistroEntradas[[#This Row],[Data do Caixa Previsto]]<TODAY(),TbRegistroEntradas[[#This Row],[Data do Caixa Realizado]]=""),"Vencida","Não Vencida") -> Não Vencida | P32: =IF(TbRegistroEntradas[[#This Row],[Data da Competência]]=TbRegistroEntradas[[#This Row],[Data do Caixa Previsto]],"Vista","Prazo") -> Prazo | Q32: =IF(TbRegistroEntradas[[#This Row],[Data do Caixa Realizado]]<>"", IF(TbRegistroEntradas[[#This Row],[Data do Caixa Realizado]]>TbRegistroEntradas[[#This Row],[Data do Caixa Previsto]], TbRegistroEntradas[[#This Row],[Data do Caixa Realizado]]-TbRegistroEntradas[[#This Row],[Data do Caixa Previsto]], 0 ), IF(TODAY()>TbRegistroEntradas[[#This Row],[Data do Caixa Previsto]], TODAY()-TbRegistroEntradas[[#This Row],[Data do Caixa Previsto]], 0 ) ) -> 14
B33: 45630 | C33: 45604 | D33: 45610 | E33: Vendas de mercadorias | F33: Móveis | G33: NF5808 | H33: 547 | I33: =IF(TbRegistroEntradas[[#This Row],[Data do Caixa Realizado]]="",0,MONTH(TbRegistroEntradas[[#This Row],[Data do Caixa Previsto]])) -> 11 | J33: =IF(TbRegistroEntradas[[#This Row],[Data do Caixa Realizado]]="",0,YEAR(TbRegistroEntradas[[#This Row],[Data do Caixa Realizado]])) -> 2024 | K33: =IF(TbRegistroEntradas[[#This Row],[Data da Competência]]="",0,MONTH(TbRegistroEntradas[[#This Row],[Data da Competência]])) -> 11 | L33: =IF(TbRegistroEntradas[[#This Row],[Data da Competência]]="",0,YEAR(TbRegistroEntradas[[#This Row],[Data da Competência]])) -> 2024 | M33: =IF(TbRegistroEntradas[[#This Row],[Data do Caixa Previsto]]="",0,MONTH(TbRegistroEntradas[[#This Row],[Data do Caixa Previsto]])) -> 11 | N33: =IF(TbRegistroEntradas[[#This Row],[Data do Caixa Previsto]]="",0,YEAR(TbRegistroEntradas[[#This Row],[Data do Caixa Previsto]])) -> 2024 | O33: =IF(AND(TbRegistroEntradas[[#This Row],[Data do Caixa Previsto]]<TODAY(),TbRegistroEntradas[[#This Row],[Data do Caixa Realizado]]=""),"Vencida","Não Vencida") -> Não Vencida | P33: =IF(TbRegistroEntradas[[#This Row],[Data da Competência]]=TbRegistroEntradas[[#This Row],[Data do Caixa Previsto]],"Vista","Prazo") -> Prazo | Q33: =IF(TbRegistroEntradas[[#This Row],[Data do Caixa Realizado]]<>"", IF(TbRegistroEntradas[[#This Row],[Data do Caixa Realizado]]>TbRegistroEntradas[[#This Row],[Data do Caixa Previsto]], TbRegistroEntradas[[#This Row],[Data do Caixa Realizado]]-TbRegistroEntradas[[#This Row],[Data do Caixa Previsto]], 0 ), IF(TODAY()>TbRegistroEntradas[[#This Row],[Data do Caixa Previsto]], TODAY()-TbRegistroEntradas[[#This Row],[Data do Caixa Previsto]], 0 ) ) -> 20
B34: 45647 | C34: 45608 | D34: 45647 | E34: Vendas de mercadorias | F34: Móveis | G34: NF2852 | H34: 1221 | I34: =IF(TbRegistroEntradas[[#This Row],[Data do Caixa Realizado]]="",0,MONTH(TbRegistroEntradas[[#This Row],[Data do Caixa Previsto]])) -> 12 | J34: =IF(TbRegistroEntradas[[#This Row],[Data do Caixa Realizado]]="",0,YEAR(TbRegistroEntradas[[#This Row],[Data do Caixa Realizado]])) -> 2024 | K34: =IF(TbRegistroEntradas[[#This Row],[Data da Competência]]="",0,MONTH(TbRegistroEntradas[[#This Row],[Data da Competência]])) -> 11 | L34: =IF(TbRegistroEntradas[[#This Row],[Data da Competência]]="",0,YEAR(TbRegistroEntradas[[#This Row],[Data da Competência]])) -> 2024 | M34: =IF(TbRegistroEntradas[[#This Row],[Data do Caixa Previsto]]="",0,MONTH(TbRegistroEntradas[[#This Row],[Data do Caixa Previsto]])) -> 12 | N34: =IF(TbRegistroEntradas[[#This Row],[Data do Caixa Previsto]]="",0,YEAR(TbRegistroEntradas[[#This Row],[Data do Caixa Previsto]])) -> 2024 | O34: =IF(AND(TbRegistroEntradas[[#This Row],[Data do Caixa Previsto]]<TODAY(),TbRegistroEntradas[[#This Row],[Data do Caixa Realizado]]=""),"Vencida","Não Vencida") -> Não Vencida | P34: =IF(TbRegistroEntradas[[#This Row],[Data da Competência]]=TbRegistroEntradas[[#This Row],[Data do Caixa Previsto]],"Vista","Prazo") -> Prazo | Q34: =IF(TbRegistroEntradas[[#This Row],[Data do Caixa Realizado]]<>"", IF(TbRegistroEntradas[[#This Row],[Data do Caixa Realizado]]>TbRegistroEntradas[[#This Row],[Data do Caixa Previsto]], TbRegistroEntradas[[#This Row],[Data do Caixa Realizado]]-TbRegistroEntradas[[#This Row],[Data do Caixa Previsto]], 0 ), IF(TODAY()>TbRegistroEntradas[[#This Row],[Data do Caixa Previsto]], TODAY()-TbRegistroEntradas[[#This Row],[Data do Caixa Previsto]], 0 ) ) -> 0
... B40: 45679 | C40: 45620 | D40: 45679 | E40: Vendas de mercadorias | F40: Informática | G40: NF6190 | H40: 3992 | I40: =IF(TbRegistroEntradas[[#This Row],[Data do Caixa Realizado]]="",0,MONTH(TbRegistroEntradas[[#This Row],[Data do Caixa Previsto]])) -> 1 | J40: =IF(TbRegistroEntradas[[#This Row],[Data do Caixa Realizado]]="",0,YEAR(TbRegistroEntradas[[#This Row],[Data do Caixa Realizado]])) -> 2025 | K40: =IF(TbRegistroEntradas[[#This Row],[Data da Competência]]="",0,MONTH(TbRegistroEntradas[[#This Row],[Data da Competência]])) -> 11 | L40: =IF(TbRegistroEntradas[[#This Row],[Data da Competência]]="",0,YEAR(TbRegistroEntradas[[#This Row],[Data da Competência]])) -> 2024 | M40: =IF(TbRegistroEntradas[[#This Row],[Data do Caixa Previsto]]="",0,MONTH(TbRegistroEntradas[[#This Row],[Data do Caixa Previsto]])) -> 1 | N40: =IF(TbRegistroEntradas[[#This Row],[Data do Caixa Previsto]]="",0,YEAR(TbRegistroEntradas[[#This Row],[Data do Caixa Previsto]])) -> 2025 | O40: =IF(AND(TbRegistroEntradas[[#This Row],[Data do Caixa Previsto]]<TODAY(),TbRegistroEntradas[[#This Row],[Data do Caixa Realizado]]=""),"Vencida","Não Vencida") -> Não Vencida | P40: =IF(TbRegistroEntradas[[#This Row],[Data da Competência]]=TbRegistroEntradas[[#This Row],[Data do Caixa Previsto]],"Vista","Prazo") -> Prazo | Q40: =IF(TbRegistroEntradas[[#This Row],[Data do Caixa Realizado]]<>"", IF(TbRegistroEntradas[[#This Row],[Data do Caixa Realizado]]>TbRegistroEntradas[[#This Row],[Data do Caixa Previsto]], TbRegistroEntradas[[#This Row],[Data do Caixa Realizado]]-TbRegistroEntradas[[#This Row],[Data do Caixa Previsto]], 0 ), IF(TODAY()>TbRegistroEntradas[[#This Row],[Data do Caixa Previsto]], TODAY()-TbRegistroEntradas[[#This Row],[Data do Caixa Previsto]], 0 ) ) -> 0
